2022-05-18 08:33:25,769 - INFO - ###########################################
2022-05-18 08:33:25,770 - INFO - /home/php/Documents/Thierry/set_etudiants/Omar RESUTATS/20170914-E6onPLL/b3c3g-2017.09.14-15.47.33.200.jpk-nt-force
2022-05-18 08:33:25,770 - INFO - ###########################################
2022-05-18 08:33:25,770 - ERROR - KeyError
2022-05-18 08:33:25,770 - ERROR - 13495
2022-05-18 08:33:25,770 - ERROR - Traceback (most recent call last):
  File "/home/php/anaconda3/lib/python3.9/site-packages/pandas/core/indexes/range.py", line 385, in get_loc
    return self._range.index(new_key)
ValueError: 13495 is not in range

The above exception was the direct cause of the following exception:

Traceback (most recent call last):
  File "/home/php/Documents/Thierry/OTAnalysis/otanalysis/controller/controller.py", line 226, in create_dict_curves
    error = new_curve.analyzed_curve(
  File "/home/php/Documents/Thierry/OTAnalysis/otanalysis/model/class_curve.py", line 1029, in analyzed_curve
    type_curve = self.curve_return_analyze(methods, type_curve)
  File "/home/php/Documents/Thierry/OTAnalysis/otanalysis/model/class_curve.py", line 812, in curve_return_analyze
    type_curve = self.classification(methods, type_curve)
  File "/home/php/Documents/Thierry/OTAnalysis/otanalysis/model/class_curve.py", line 902, in classification
    jump_time_start_pull = time_data[index_force_max] - \
  File "/home/php/anaconda3/lib/python3.9/site-packages/pandas/core/series.py", line 959, in __getitem__
    return self._get_value(key)
  File "/home/php/anaconda3/lib/python3.9/site-packages/pandas/core/series.py", line 1070, in _get_value
    loc = self.index.get_loc(label)
  File "/home/php/anaconda3/lib/python3.9/site-packages/pandas/core/indexes/range.py", line 387, in get_loc
    raise KeyError(key) from err
KeyError: 13495

2022-05-18 08:33:25,770 - INFO - ###########################################
2022-05-18 08:38:32,680 - INFO - ###########################################
2022-05-18 08:38:32,681 - INFO - b2c2-2017.09.07-15.47.40.402
2022-05-18 08:38:32,681 - INFO - ###########################################
2022-05-18 08:38:32,715 - ERROR - Can only compare identically-labeled Series objects
2022-05-18 08:38:32,716 - ERROR - Traceback (most recent call last):
  File "/home/php/Documents/Thierry/OTAnalysis/otanalysis/view/class_view.py", line 1339, in optical_effect
    fig = self.current_curve.correction_optical_effect_object.manual_correction(
  File "/home/php/Documents/Thierry/OTAnalysis/otanalysis/model/class_optical_effect.py", line 145, in manual_correction
    fitted_press, length_stop_press = self.fitting_and_contact_theorical(
  File "/home/php/Documents/Thierry/OTAnalysis/otanalysis/model/class_optical_effect.py", line 88, in fitting_and_contact_theorical
    self.time_data_press == value_contact_point_theorical)[0][0]
  File "/home/php/anaconda3/lib/python3.9/site-packages/pandas/core/ops/common.py", line 70, in new_method
    return method(self, other)
  File "/home/php/anaconda3/lib/python3.9/site-packages/pandas/core/arraylike.py", line 40, in __eq__
    return self._cmp_method(other, operator.eq)
  File "/home/php/anaconda3/lib/python3.9/site-packages/pandas/core/series.py", line 5614, in _cmp_method
    raise ValueError("Can only compare identically-labeled Series objects")
ValueError: Can only compare identically-labeled Series objects

2022-05-18 08:38:32,716 - INFO - ###########################################
2022-05-18 09:08:36,421 - WARNING - No handles with labels found to put in legend.
