2022-05-18 09:16:48,146 - INFO - ###########################################
2022-05-18 09:16:48,146 - INFO - /home/php/Documents/Thierry/set_etudiants/Omar RESUTATS/20170914-E6onPLL/b3c3g-2017.09.14-15.47.33.200.jpk-nt-force
2022-05-18 09:16:48,146 - INFO - ###########################################
2022-05-18 09:16:48,146 - ERROR - KeyError
2022-05-18 09:16:48,146 - ERROR - 13495
2022-05-18 09:16:48,147 - ERROR - Traceback (most recent call last):
  File "/home/php/anaconda3/lib/python3.9/site-packages/pandas/core/indexes/range.py", line 385, in get_loc
    return self._range.index(new_key)
ValueError: 13495 is not in range

The above exception was the direct cause of the following exception:

Traceback (most recent call last):
  File "/home/php/Documents/Thierry/OTAnalysis/otanalysis/controller/controller.py", line 226, in create_dict_curves
    error = new_curve.analyzed_curve(
  File "/home/php/Documents/Thierry/OTAnalysis/otanalysis/model/class_curve.py", line 1026, in analyzed_curve
    type_curve = self.curve_return_analyze(methods, type_curve)
  File "/home/php/Documents/Thierry/OTAnalysis/otanalysis/model/class_curve.py", line 812, in curve_return_analyze
    type_curve = self.classification(methods, type_curve)
  File "/home/php/Documents/Thierry/OTAnalysis/otanalysis/model/class_curve.py", line 902, in classification
    jump_time_start_pull = time_data[index_force_max] - \
  File "/home/php/anaconda3/lib/python3.9/site-packages/pandas/core/series.py", line 959, in __getitem__
    return self._get_value(key)
  File "/home/php/anaconda3/lib/python3.9/site-packages/pandas/core/series.py", line 1070, in _get_value
    loc = self.index.get_loc(label)
  File "/home/php/anaconda3/lib/python3.9/site-packages/pandas/core/indexes/range.py", line 387, in get_loc
    raise KeyError(key) from err
KeyError: 13495

2022-05-18 09:16:48,147 - INFO - ###########################################
2022-05-18 09:52:22,530 - INFO - ###########################################
2022-05-18 09:52:22,531 - INFO - b3c3-2017.09.07-16.40.59.840
2022-05-18 09:52:22,531 - INFO - ###########################################
2022-05-18 09:52:22,552 - ERROR - index 0 is out of bounds for axis 0 with size 0
2022-05-18 09:52:22,552 - ERROR - Traceback (most recent call last):
  File "/home/php/Documents/Thierry/OTAnalysis/otanalysis/view/class_view.py", line 1339, in optical_effect
    fig = self.current_curve.correction_optical_effect_object.manual_correction(
  File "/home/php/Documents/Thierry/OTAnalysis/otanalysis/model/class_optical_effect.py", line 148, in manual_correction
    fitted_press, length_stop_press = self.fitting_and_contact_theorical(
  File "/home/php/Documents/Thierry/OTAnalysis/otanalysis/model/class_optical_effect.py", line 86, in fitting_and_contact_theorical
    index_contact_point_theorical = list_index[0]
  File "/home/php/anaconda3/lib/python3.9/site-packages/pandas/core/indexes/base.py", line 5039, in __getitem__
    return getitem(key)
IndexError: index 0 is out of bounds for axis 0 with size 0

2022-05-18 09:52:22,552 - INFO - ###########################################
