2022-05-18 09:55:42,733 - INFO - ###########################################
2022-05-18 09:55:42,733 - INFO - /home/php/Documents/Thierry/set_etudiants/Omar RESUTATS/20170914-E6onPLL/b3c3g-2017.09.14-15.47.33.200.jpk-nt-force
2022-05-18 09:55:42,733 - INFO - ###########################################
2022-05-18 09:55:42,734 - ERROR - KeyError
2022-05-18 09:55:42,734 - ERROR - 13495
2022-05-18 09:55:42,734 - ERROR - Traceback (most recent call last):
  File "/home/php/anaconda3/lib/python3.9/site-packages/pandas/core/indexes/range.py", line 385, in get_loc
    return self._range.index(new_key)
ValueError: 13495 is not in range

The above exception was the direct cause of the following exception:

Traceback (most recent call last):
  File "/home/php/Documents/Thierry/OTAnalysis/otanalysis/controller/controller.py", line 226, in create_dict_curves
    error = new_curve.analyzed_curve(
  File "/home/php/Documents/Thierry/OTAnalysis/otanalysis/model/class_curve.py", line 1024, in analyzed_curve
    type_curve = self.curve_return_analyze(methods, type_curve)
  File "/home/php/Documents/Thierry/OTAnalysis/otanalysis/model/class_curve.py", line 812, in curve_return_analyze
    type_curve = self.classification(methods, type_curve)
  File "/home/php/Documents/Thierry/OTAnalysis/otanalysis/model/class_curve.py", line 902, in classification
    jump_time_start_pull = time_data[index_force_max] - time_data[index_release]
  File "/home/php/anaconda3/lib/python3.9/site-packages/pandas/core/series.py", line 959, in __getitem__
    return self._get_value(key)
  File "/home/php/anaconda3/lib/python3.9/site-packages/pandas/core/series.py", line 1070, in _get_value
    loc = self.index.get_loc(label)
  File "/home/php/anaconda3/lib/python3.9/site-packages/pandas/core/indexes/range.py", line 387, in get_loc
    raise KeyError(key) from err
KeyError: 13495

2022-05-18 09:55:42,734 - INFO - ###########################################
2022-05-18 09:56:03,903 - INFO - ###########################################
2022-05-18 09:56:03,904 - INFO - b3c3-2017.09.07-16.40.59.840
2022-05-18 09:56:03,904 - INFO - ###########################################
2022-05-18 09:56:03,905 - ERROR - 'NaN'
2022-05-18 09:56:03,905 - ERROR - Traceback (most recent call last):
  File "/home/php/Documents/Thierry/OTAnalysis/otanalysis/view/class_view.py", line 1339, in optical_effect
    fig = self.current_curve.correction_optical_effect_object.manual_correction(
  File "/home/php/Documents/Thierry/OTAnalysis/otanalysis/model/class_optical_effect.py", line 150, in manual_correction
    fitted_press, length_stop_press = self.fitting_and_contact_theorical(
  File "/home/php/Documents/Thierry/OTAnalysis/otanalysis/model/class_optical_effect.py", line 95, in fitting_and_contact_theorical
    'index': index_contact_point_theorical, 'value': self.force_data_press[index_contact_point_theorical]}
  File "/home/php/anaconda3/lib/python3.9/site-packages/pandas/core/series.py", line 959, in __getitem__
    return self._get_value(key)
  File "/home/php/anaconda3/lib/python3.9/site-packages/pandas/core/series.py", line 1070, in _get_value
    loc = self.index.get_loc(label)
  File "/home/php/anaconda3/lib/python3.9/site-packages/pandas/core/indexes/range.py", line 389, in get_loc
    raise KeyError(key)
KeyError: 'NaN'

2022-05-18 09:56:03,905 - INFO - ###########################################
